Validating models...

0 errors found
May 10, 2014 - 10:45:38
Django version 1.6.4, using settings 'blog.settings'
Starting development server at http://127.0.0.1:8000/
Quit the server with CONTROL-C.
[10/May/2014 10:46:05] "GET / HTTP/1.1" 200 1757
[10/May/2014 10:46:05] "GET / HTTP/1.1" 200 1757
[10/May/2014 10:46:06] "GET / HTTP/1.1" 200 1757
[10/May/2014 10:46:12] "GET / HTTP/1.1" 200 1757
[10/May/2014 10:46:12] "GET / HTTP/1.1" 200 1757
[10/May/2014 10:46:12] "GET / HTTP/1.1" 200 1757
[10/May/2014 10:46:12] "GET / HTTP/1.1" 200 1757
[10/May/2014 10:46:12] "GET / HTTP/1.1" 200 1757
[10/May/2014 10:46:13] "GET / HTTP/1.1" 200 1757
[10/May/2014 10:46:13] "GET / HTTP/1.1" 200 1757
[10/May/2014 10:46:13] "GET / HTTP/1.1" 200 1757
Validating models...

0 errors found
May 10, 2014 - 10:46:04
Django version 1.6.4, using settings 'blog.settings'
Starting development server at http://127.0.0.1:8000/
Quit the server with CONTROL-C.
Traceback (most recent call last):
  File "./manage.py", line 10, in <module>
    execute_from_command_line(sys.argv)
  File "/usr/local/lib/python2.7/dist-packages/django/core/management/__init__.py", line 399, in execute_from_command_line
    utility.execute()
  File "/usr/local/lib/python2.7/dist-packages/django/core/management/__init__.py", line 392, in execute
    self.fetch_command(subcommand).run_from_argv(self.argv)
  File "/usr/local/lib/python2.7/dist-packages/django/core/management/__init__.py", line 261, in fetch_command
    commands = get_commands()
  File "/usr/local/lib/python2.7/dist-packages/django/core/management/__init__.py", line 107, in get_commands
    apps = settings.INSTALLED_APPS
  File "/usr/local/lib/python2.7/dist-packages/django/conf/__init__.py", line 54, in __getattr__
    self._setup(name)
  File "/usr/local/lib/python2.7/dist-packages/django/conf/__init__.py", line 49, in _setup
    self._wrapped = Settings(settings_module)
  File "/usr/local/lib/python2.7/dist-packages/django/conf/__init__.py", line 128, in __init__
    mod = importlib.import_module(self.SETTINGS_MODULE)
  File "/usr/local/lib/python2.7/dist-packages/django/utils/importlib.py", line 40, in import_module
    __import__(name)
  File "/home/wangchi/Git/studying/django/blog/blog/settings.py", line 61
SyntaxError: Non-ASCII character '\xe8' in file /home/wangchi/Git/studying/django/blog/blog/settings.py on line 61, but no encoding declared; see http://www.python.org/peps/pep-0263.html for details
